Workbook

Sheet DATA
A1: Date | B1: ^AEX | C1: ^AORD | D1: ^FTSE | E1: ^GSPC | F1: ^GSPTSE | G1: ^HSI | H1: ^N225
A2: 31413 | B2: =VLOOKUP($A2,returns!A2:H521,2,FALSE) -> #N/A | C2: =VLOOKUP($A2,returns!$A$2:H$521,3,FALSE) -> #N/A | D2: =VLOOKUP($A2,returns!$A$2:$H$521,3,FALSE) -> #N/A | E2: =VLOOKUP($A2,returns!$A$2:$H$521,3,FALSE) -> #N/A | F2: =VLOOKUP($A2,returns!$A$2:$H$521,3,FALSE) -> #N/A | G2: =VLOOKUP($A2,returns!$A$2:$H$521,3,FALSE) -> #N/A | H2: =VLOOKUP($A2,returns!$A$2:$H$521,3,FALSE) -> #N/A
A3: 31414 | B3: =VLOOKUP(A3,returns!$A$2:$H$522,2,FALSE) -> 121.22 | C3: =VLOOKUP($A3,returns!$A$2:H$521,3,FALSE) -> 1010.8 | D3: =VLOOKUP($A3,returns!$A$2:$H$521,3,FALSE) -> 1010.8 | E3: =VLOOKUP($A3,returns!$A$2:$H$521,3,FALSE) -> 1010.8 | F3: =VLOOKUP($A3,returns!$A$2:$H$521,3,FALSE) -> 1010.8 | G3: =VLOOKUP($A3,returns!$A$2:$H$521,3,FALSE) -> 1010.8 | H3: =VLOOKUP($A3,returns!$A$2:$H$521,3,FALSE) -> 1010.8
A4: 31415 | B4: =VLOOKUP(A4,returns!$A$2:$H$522,2,FALSE) -> 121.52 | C4: =VLOOKUP($A4,returns!$A$2:H$521,3,FALSE) -> 1020.4 | D4: =VLOOKUP($A4,returns!$A$2:$H$521,3,FALSE) -> 1020.4 | E4: =VLOOKUP($A4,returns!$A$2:$H$521,3,FALSE) -> 1020.4 | F4: =VLOOKUP($A4,returns!$A$2:$H$521,3,FALSE) -> 1020.4 | G4: =VLOOKUP($A4,returns!$A$2:$H$521,3,FALSE) -> 1020.4 | H4: =VLOOKUP($A4,returns!$A$2:$H$521,3,FALSE) -> 1020.4
A5: 31416 | B5: =VLOOKUP(A5,returns!$A$2:$H$522,2,FALSE) -> #N/A | C5: =VLOOKUP($A5,returns!$A$2:H$521,3,FALSE) -> #N/A | D5: =VLOOKUP($A5,returns!$A$2:$H$521,3,FALSE) -> #N/A | E5: =VLOOKUP($A5,returns!$A$2:$H$521,3,FALSE) -> #N/A | F5: =VLOOKUP($A5,returns!$A$2:$H$521,3,FALSE) -> #N/A | G5: =VLOOKUP($A5,returns!$A$2:$H$521,3,FALSE) -> #N/A | H5: =VLOOKUP($A5,returns!$A$2:$H$521,3,FALSE) -> #N/A
A6: 31417 | B6: =VLOOKUP(A6,returns!$A$2:$H$522,2,FALSE) -> #N/A | C6: =VLOOKUP($A6,returns!$A$2:H$521,3,FALSE) -> #N/A | D6: =VLOOKUP($A6,returns!$A$2:$H$521,3,FALSE) -> #N/A | E6: =VLOOKUP($A6,returns!$A$2:$H$521,3,FALSE) -> #N/A | F6: =VLOOKUP($A6,returns!$A$2:$H$521,3,FALSE) -> #N/A | G6: =VLOOKUP($A6,returns!$A$2:$H$521,3,FALSE) -> #N/A | H6: =VLOOKUP($A6,returns!$A$2:$H$521,3,FALSE) -> #N/A
A7: 31418 | B7: =VLOOKUP(A7,returns!$A$2:$H$522,2,FALSE) -> 125.13 | C7: =VLOOKUP($A7,returns!$A$2:H$521,3,FALSE) -> 1028 | D7: =VLOOKUP($A7,returns!$A$2:$H$521,3,FALSE) -> 1028 | E7: =VLOOKUP($A7,returns!$A$2:$H$521,3,FALSE) -> 1028 | F7: =VLOOKUP($A7,returns!$A$2:$H$521,3,FALSE) -> 1028 | G7: =VLOOKUP($A7,returns!$A$2:$H$521,3,FALSE) -> 1028 | H7: =VLOOKUP($A7,returns!$A$2:$H$521,3,FALSE) -> 1028
A8: 31419 | B8: =VLOOKUP(A8,returns!$A$2:$H$522,2,FALSE) -> 124.98 | C8: =VLOOKUP($A8,returns!$A$2:H$521,3,FALSE) -> 1032.4 | D8: =VLOOKUP($A8,returns!$A$2:$H$521,3,FALSE) -> 1032.4 | E8: =VLOOKUP($A8,returns!$A$2:$H$521,3,FALSE) -> 1032.4 | F8: =VLOOKUP($A8,returns!$A$2:$H$521,3,FALSE) -> 1032.4 | G8: =VLOOKUP($A8,returns!$A$2:$H$521,3,FALSE) -> 1032.4 | H8: =VLOOKUP($A8,returns!$A$2:$H$521,3,FALSE) -> 1032.4
A9: 31420 | B9: =VLOOKUP(A9,returns!$A$2:$H$522,2,FALSE) -> 126.5 | C9: =VLOOKUP($A9,returns!$A$2:H$521,3,FALSE) -> 1041.6 | D9: =VLOOKUP($A9,returns!$A$2:$H$521,3,FALSE) -> 1041.6 | E9: =VLOOKUP($A9,returns!$A$2:$H$521,3,FALSE) -> 1041.6 | F9: =VLOOKUP($A9,returns!$A$2:$H$521,3,FALSE) -> 1041.6 | G9: =VLOOKUP($A9,returns!$A$2:$H$521,3,FALSE) -> 1041.6 | H9: =VLOOKUP($A9,returns!$A$2:$H$521,3,FALSE) -> 1041.6
A10: 31421 | B10: =VLOOKUP(A10,returns!$A$2:$H$522,2,FALSE) -> 123.56 | C10: =VLOOKUP($A10,returns!$A$2:H$521,3,FALSE) -> 1043.9 | D10: =VLOOKUP($A10,returns!$A$2:$H$521,3,FALSE) -> 1043.9 | E10: =VLOOKUP($A10,returns!$A$2:$H$521,3,FALSE) -> 1043.9 | F10: =VLOOKUP($A10,returns!$A$2:$H$521,3,FALSE) -> 1043.9 | G10: =VLOOKUP($A10,returns!$A$2:$H$521,3,FALSE) -> 1043.9 | H10: =VLOOKUP($A10,returns!$A$2:$H$521,3,FALSE) -> 1043.9
A11: 31422 | B11: =VLOOKUP(A11,returns!$A$2:$H$522,2,FALSE) -> 123.83 | C11: =VLOOKUP($A11,returns!$A$2:H$521,3,FALSE) -> 1044.2 | D11: =VLOOKUP($A11,returns!$A$2:$H$521,3,FALSE) -> 1044.2 | E11: =VLOOKUP($A11,returns!$A$2:$H$521,3,FALSE) -> 1044.2 | F11: =VLOOKUP($A11,returns!$A$2:$H$521,3,FALSE) -> 1044.2 | G11: =VLOOKUP($A11,returns!$A$2:$H$521,3,FALSE) -> 1044.2 | H11: =VLOOKUP($A11,returns!$A$2:$H$521,3,FALSE) -> 1044.2
A12: 31423 | B12: =VLOOKUP(A12,returns!$A$2:$H$522,2,FALSE) -> #N/A | C12: =VLOOKUP($A12,returns!$A$2:H$521,3,FALSE) -> #N/A | D12: =VLOOKUP($A12,returns!$A$2:$H$521,3,FALSE) -> #N/A | E12: =VLOOKUP($A12,returns!$A$2:$H$521,3,FALSE) -> #N/A | F12: =VLOOKUP($A12,returns!$A$2:$H$521,3,FALSE) -> #N/A | G12: =VLOOKUP($A12,returns!$A$2:$H$521,3,FALSE) -> #N/A | H12: =VLOOKUP($A12,returns!$A$2:$H$521,3,FALSE) -> #N/A
A13: 31424 | B13: =VLOOKUP(A13,returns!$A$2:$H$522,2,FALSE) -> #N/A | C13: =VLOOKUP($A13,returns!$A$2:H$521,3,FALSE) -> #N/A | D13: =VLOOKUP($A13,returns!$A$2:$H$521,3,FALSE) -> #N/A | E13: =VLOOKUP($A13,returns!$A$2:$H$521,3,FALSE) -> #N/A | F13: =VLOOKUP($A13,returns!$A$2:$H$521,3,FALSE) -> #N/A | G13: =VLOOKUP($A13,returns!$A$2:$H$521,3,FALSE) -> #N/A | H13: =VLOOKUP($A13,returns!$A$2:$H$521,3,FALSE) -> #N/A
A14: 31425 | B14: =VLOOKUP(A14,returns!$A$2:$H$522,2,FALSE) -> 121.62 | C14: =VLOOKUP($A14,returns!$A$2:H$521,3,FALSE) -> 1051.1 | D14: =VLOOKUP($A14,returns!$A$2:$H$521,3,FALSE) -> 1051.1 | E14: =VLOOKUP($A14,returns!$A$2:$H$521,3,FALSE) -> 1051.1 | F14: =VLOOKUP($A14,returns!$A$2:$H$521,3,FALSE) -> 1051.1 | G14: =VLOOKUP($A14,returns!$A$2:$H$521,3,FALSE) -> 1051.1 | H14: =VLOOKUP($A14,returns!$A$2:$H$521,3,FALSE) -> 1051.1
... A731: 32142 | B731: =VLOOKUP(A731,returns!$A$2:$H$522,2,FALSE) -> 0 | C731: =VLOOKUP($A731,returns!$A$2:H$521,3,FALSE) -> 1320 | D731: =VLOOKUP($A731,returns!$A$2:$H$521,3,FALSE) -> 1320 | E731: =VLOOKUP($A731,returns!$A$2:$H$521,3,FALSE) -> 1320 | F731: =VLOOKUP($A731,returns!$A$2:$H$521,3,FALSE) -> 1320 | G731: =VLOOKUP($A731,returns!$A$2:$H$521,3,FALSE) -> 1320 | H731: =VLOOKUP($A731,returns!$A$2:$H$521,3,FALSE) -> 1320

Sheet Short-term interest Rates daily
A1: Date | B1: Australia_3M_Bank_Accepted_Bill | C1: Canada_3mtbill | D1: UK_3mbond_yield | E1: US_3MTBILLYIELD
A2: 31412 | B2: 19 | C2: #N/A | D2: #N/A | E2: #N/A
A3: 31413 | C3: 0 | D3: 11.23 | E3: #N/A
A4: 31414 | B4: 18.75 | C4: 9.39 | D4: 11.21 | E4: 7.1
A5: 31415 | B5: 18.5 | C5: 9.68 | D5: 11.21 | E5: 7.07
A6: 31418 | B6: 19 | C6: 9.82 | D6: 11.25 | E6: 7.06
A7: 31419 | B7: 18.88 | C7: 9.72 | D7: 11.5 | E7: 7.03
A8: 31420 | B8: 18.75 | C8: 9.91 | D8: 11.88 | E8: 7.17
A9: 31421 | B9: 19.13 | C9: 9.96 | D9: 12.44 | E9: 7.18
A10: 31422 | B10: 19.25 | C10: 9.89 | D10: 12.25 | E10: 7.21
A11: 31425 | B11: 19.25 | C11: 10 | D11: 12.3 | E11: 7.24
A12: 31426 | B12: 19.38 | C12: 10.09 | D12: 12.3 | E12: 7.24
A13: 31427 | B13: 19.25 | C13: 10.13 | D13: 12.5 | E13: 7.19
A14: 31428 | B14: 19.25 | C14: 10.12 | D14: 12.22 | E14: 7.08
A15: 31429 | B15: 19 | C15: 10.09 | D15: 12.24 | E15: 7.11
... A20: 31436 | B20: 18.75 | C20: 10.28 | D20: 12.82 | E20: 6.97
A21: 31439 | C21: 10.43 | D21: 12.72 | E21: 6.95
A22: 31440 | B22: 18.75 | C22: 10.5 | D22: 12.22 | E22: 6.92
A23: 31441 | B23: 18.5 | C23: 10.45 | D23: 12.28 | E23: 7.03
A24: 31442 | B24: 18.25 | C24: 10.7 | D24: 12.24 | E24: 7.04
A25: 31443 | B25: 18.75 | C25: 10.59 | D25: 12.24 | E25: 6.97
A26: 31446 | B26: 18.5 | C26: 10.74 | D26: 12.57 | E26: 7
A27: 31447 | B27: 18.5 | C27: 10.78 | D27: 12.69 | E27: 6.98
A28: 31448 | B28: 18.63 | C28: 11.08 | D28: 12.21 | E28: 7.01
A29: 31449 | B29: 18.5 | C29: 11.23 | D29: 12.2 | E29: 7.1
A30: 31450 | B30: 18.63 | C30: 11.33 | D30: 12.2 | E30: 7.21
A31: 31453 | B31: 18.75 | C31: 11.38 | D31: 12.2 | E31: 7.2
A32: 31454 | B32: 19.5 | C32: 11.4 | D32: 12.2 | E32: 7.11
A33: 31455 | B33: 19.25 | C33: 11.4 | D33: 12.27 | E33: 7.11
... A64: 31498 | B64: 16.75 | C64: 10.01 | D64: 10.97 | E64: 6.34
A65: 31499 | C65: 0 | D65: 10.97 | E65: 0
A66: 31502 | C66: 10.1 | D66: 10.97 | E66: 6.34
A67: 31503 | B67: 17 | C67: 10.09 | D67: 10.9 | E67: 6.33
A68: 31504 | B68: 17 | C68: 10.08 | D68: 10.87 | E68: 6.34
A69: 31505 | B69: 17 | C69: 9.92 | D69: 10.82 | E69: 6.33
A70: 31506 | B70: 16.38 | C70: 9.71 | D70: 10.85 | E70: 6.23
A71: 31509 | B71: 17.38 | C71: 9.55 | D71: 10.65 | E71: 6.24
A72: 31510 | B72: 17.75 | C72: 9.38 | D72: 10.46 | E72: 6.13
A73: 31511 | B73: 18 | C73: 9.23 | D73: 10.18 | E73: 6.01
A74: 31512 | B74: 18.75 | C74: 9.08 | D74: 10.13 | E74: 6.02
...

Sheet returns
A1: Date | B1: ^AEX | C1: ^AORD | D1: ^FTSE | E1: ^GSPC | F1: ^GSPTSE | G1: ^HSI | H1: ^N225
A2: 31414 | B2: 121.22 | C2: 1010.8 | D2: 1420.5 | E2: 209.59 | F2: 2874.18 | G2: 1774.38 | H2: 13083.18
A3: 31415 | B3: 121.52 | C3: 1020.4 | D3: 1429.8 | E3: 210.88 | F3: 2874.08 | G3: 1791.23 | H3: 13083.18
A4: 31418 | B4: 125.13 | C4: 1028 | D4: 1424.1 | E4: 210.65 | F4: 2859.92 | G4: 1796.59 | H4: 13053.79
A5: 31419 | B5: 124.98 | C5: 1032.4 | D5: 1415.2 | E5: 213.8 | F5: 2881.26 | G5: 1815.53 | H5: 12991.24
A6: 31420 | B6: 126.5 | C6: 1041.6 | D6: 1404.2 | E6: 207.97 | F6: 2852.54 | G6: 1826.84 | H6: 13056.42
A7: 31421 | B7: 123.56 | C7: 1043.9 | D7: 1379.6 | E7: 206.11 | F7: 2817.53 | G7: 1798.51 | H7: 13034.19
A8: 31422 | B8: 123.83 | C8: 1044.2 | D8: 1394.5 | E8: 205.96 | F8: 2810.44 | G8: 1807.94 | H8: 12998.21
A9: 31425 | B9: 121.62 | C9: 1051.1 | D9: 1384.6 | E9: 206.72 | F9: 2802.76 | G9: 1799.61 | H9: 12977.02
A10: 31426 | B10: 122.62 | C10: 1048.9 | D10: 1370.1 | E10: 206.64 | F10: 2804.86 | G10: 1782.23 | H10: 12928.6
A11: 31427 | B11: 124.53 | C11: 1050.5 | D11: 1390.5 | E11: 208.26 | F11: 2846.35 | G11: 1783.66 | H11: 12928.6
A12: 31428 | B12: 125.98 | C12: 1060.9 | D12: 1394.5 | E12: 209.17 | F12: 2868.9 | G12: 1797.22 | H12: 13027.13
A13: 31429 | B13: 125.45 | C13: 1066.7 | D13: 1396 | E13: 208.43 | F13: 2862.01 | G13: 1806.86 | H13: 13009.7
... A18: 31436 | B18: 121.62 | C18: 1052.9 | D18: 1392 | E18: 206.43 | F18: 2802.96 | G18: 1745.8 | H18: 12904.2
A19: 31439 | B19: 122.19 | D19: 1405 | E19: 207.39 | F19: 2820.72 | G19: 1744.11 | H19: 12983.14
A20: 31440 | B20: 120.99 | C20: 1055.6 | D20: 1426.3 | E20: 209.81 | F20: 2830.69 | G20: 1754.38 | H20: 12993.69
A21: 31441 | B21: 120.02 | C21: 1060.5 | D21: 1421 | E21: 210.29 | F21: 2849.64 | G21: 1736.35 | H21: 12957.14
A22: 31442 | B22: 117.76 | C22: 1074.2 | D22: 1429.1 | E22: 209.33 | F22: 2837.28 | G22: 1720.21 | H22: 12949.04
A23: 31443 | B23: 119.53 | C23: 1075.1 | D23: 1435 | E23: 211.78 | F23: 2835.78 | G23: 1695.78 | H23: 13024.3
A24: 31446 | B24: 121.25 | C24: 1072.9 | D24: 1425.1 | E24: 213.96 | F24: 2835.68 | G24: 1702.38 | H24: 13086.47
A25: 31447 | B25: 122.5 | C25: 1075.6 | D25: 1431.6 | E25: 212.79 | F25: 2775.13 | G25: 1728.81 | H25: 13138.09
A26: 31448 | B26: 122.01 | C26: 1060.7 | D26: 1424.1 | E26: 212.96 | F26: 2764.56 | G26: 1723.08 | H26: 13185.66
A27: 31449 | B27: 121.61 | C27: 1066.9 | D27: 1426.9 | E27: 213.47 | F27: 2793.89 | G27: 1719.67 | H27: 13186.61
A28: 31450 | B28: 120.55 | C28: 1069.4 | D28: 1445 | E28: 214.56 | F28: 2791.69 | G28: 1734.04 | H28: 13212.13
A29: 31453 | B29: 121.1 | C29: 1068.9 | D29: 1461.5 | E29: 216.24 | F29: 2785.91 | G29: #N/A | H29: 13226.07
A30: 31454 | B30: 120.05 | C30: 1064.5 | D30: 1453.9 | E30: 215.92 | F30: 2761.67 | G30: #N/A | H30: 13226.1
A31: 31455 | B31: 119.15 | C31: 1055.2 | D31: 1470 | E31: 215.97 | F31: 2774.04 | G31: 1743.03 | H31: 13300.58
A32: 31456 | B32: 118.36 | C32: 1039.7 | D32: 1473.5 | E32: 217.4 | F32: 2753.79 | G32: 1746.4 | H32: 13293.8
A33: 31457 | B33: 118.78 | C33: 1046.7 | D33: 1477.9 | E33: 219.76 | F33: 2754.29 | G33: 1777.54 | H33: 13342.78
A34: 31460 | B34: 118.59 | C34: 1048.5 | D34: 1475.3 | G34: 1783.08 | H34: 13447.91
A35: 31461 | B35: 118.23 | C35: 1047.1 | D35: 1491.9 | E35: 222.45 | F35: 2774.84 | G35: 1771.41 | H35: 13436.23
A36: 31462 | B36: 116.47 | C36: 1049.6 | D36: 1491.4 | E36: 219.76 | F36: 2783.61 | G36: 1751.67 | H36: 13466.65
A37: 31463 | B37: 115.73 | C37: 1052.3 | D37: 1492.1 | E37: 222.22 | F37: 2794.29 | G37: 1733.17 | H37: 13355.41
A38: 31464 | B38: 115.54 | C38: 1057 | D38: 1518 | E38: 224.62 | F38: 2802.67 | G38: 1747.06 | H38: 13394.31
A39: 31467 | B39: 114.3 | C39: 1062 | D39: 1533 | E39: 224.34 | F39: 2794.59 | G39: 1742.37 | H39: 13503.49
A40: 31468 | B40: 112.54 | C40: 1046.6 | D40: 1527.7 | E40: 223.79 | F40: 2801.37 | G40: 1746.05 | H40: 13576.3
A41: 31469 | B41: 112.92 | C41: 1047 | D41: 1534.6 | E41: 224.04 | F41: 2820.02 | G41: 1746.3 | H41: 13621.7
A42: 31470 | B42: 111.84 | C42: 1041.6 | D42: 1549.5 | E42: 226.77 | F42: 2826.1 | G42: 1720.51 | H42: 13642.14
A43: 31471 | B43: 112.4 | C43: 1041.6 | D43: 1543.9 | E43: 226.92 | F43: 2848.55 | G43: 1695.3 | H43: 13640.83
A44: 31474 | B44: 111.3 | C44: 1041.6 | D44: 1534.9 | E44: 225.42 | F44: 2859.32 | G44: 1685.06 | H44: 13757.63
...

Sheet Policy_interest rates
A1: Date | B1: Australia | C1: Canada | D1: United_Kingdom | E1: Hong_Kong | F1: Japan | G1: Netherlands | H1: United_States | O1: Source | P1: Central bank policy rates - data | BIS Data Portal
A2: 31413 | C2: 9.49 | F2: 5 | G2: 5.5 | H2: 7.75
A3: 31414 | B3: 18.75 | C3: 9.62 | D3: 11.375 | F3: 5 | G3: 5.5 | H3: 7.75
A4: 31415 | B4: 18.5 | C4: 9.62 | D4: 11.375 | F4: 5 | G4: 5.5 | H4: 7.75
A5: 31416 | F5: 5 | G5: 5.5 | H5: 7.75
A6: 31417 | F6: 5 | G6: 5.5 | H6: 7.75
A7: 31418 | B7: 19 | C7: 9.62 | D7: 11.375 | F7: 5 | G7: 5.5 | H7: 7.75
A8: 31419 | B8: 18.88 | C8: 9.62 | D8: 11.375 | F8: 5 | G8: 5.5 | H8: 7.75
A9: 31420 | B9: 18.75 | C9: 9.62 | D9: 11.375 | F9: 5 | G9: 5.5 | H9: 7.75
A10: 31421 | B10: 19.13 | C10: 10.21 | D10: 11.375 | F10: 5 | G10: 5.5 | H10: 7.75
A11: 31422 | B11: 19.25 | C11: 10.21 | D11: 11.375 | F11: 5 | G11: 5.5 | H11: 7.75
A12: 31423 | F12: 5 | G12: 5.5 | H12: 7.75
A13: 31424 | F13: 5 | G13: 5.5 | H13: 7.75
A14: 31425 | B14: 19.25 | C14: 10.21 | D14: 11.375 | F14: 5 | G14: 5.5 | H14: 7.75
A15: 31426 | B15: 19.38 | C15: 10.21 | D15: 11.375 | F15: 5 | G15: 5.5 | H15: 7.75
A16: 31427 | B16: 19.25 | C16: 10.21 | D16: 12.375 | F16: 5 | G16: 5.5 | H16: 7.75
A17: 31428 | B17: 19.25 | C17: 10.38 | D17: 12.375 | F17: 5 | G17: 5.5 | H17: 7.75
A18: 31429 | B18: 19 | C18: 10.38 | D18: 12.375 | F18: 5 | G18: 5.5 | H18: 7.75
A19: 31430 | F19: 5 | G19: 5.5 | H19: 7.75
A20: 31431 | F20: 5 | G20: 5.5 | H20: 7.75
A21: 31432 | B21: 19 | C21: 10.38 | D21: 12.375 | F21: 5 | G21: 5.5 | H21: 7.75
A22: 31433 | B22: 19 | C22: 10.38 | D22: 12.375 | F22: 5 | G22: 5.5 | H22: 7.75
A23: 31434 | B23: 18.88 | C23: 10.38 | D23: 12.375 | F23: 5 | G23: 5.5 | H23: 7.75
A24: 31435 | B24: 18.75 | C24: 10.33 | D24: 12.375 | F24: 5 | G24: 5.5 | H24: 7.75
A25: 31436 | B25: 18.75 | C25: 10.33 | D25: 12.375 | F25: 5 | G25: 5.5 | H25: 7.75
A26: 31437 | F26: 5 | G26: 5.5 | H26: 7.75
A27: 31438 | F27: 5 | G27: 5.5 | H27: 7.75
A28: 31439 | C28: 10.33 | D28: 12.375 | F28: 5 | G28: 5.5 | H28: 7.75
A29: 31440 | B29: 18.75 | C29: 10.33 | D29: 12.375 | F29: 5 | G29: 5.5 | H29: 7.75
A30: 31441 | B30: 18.5 | C30: 10.33 | D30: 12.375 | F30: 5 | G30: 5.5 | H30: 7.75
A31: 31442 | B31: 18.25 | C31: 10.8 | D31: 12.375 | F31: 4.5 | G31: 5.5 | H31: 7.75
A32: 31443 | B32: 18.75 | C32: 10.8 | D32: 12.375 | F32: 4.5 | G32: 5.5 | H32: 7.75
A33: 31444 | F33: 4.5 | G33: 5.5 | H33: 7.75
A34: 31445 | F34: 4.5 | G34: 5.5 | H34: 7.75
A35: 31446 | B35: 18.5 | C35: 10.8 | D35: 12.375 | F35: 4.5 | G35: 5.5 | H35: 7.75
A36: 31447 | B36: 18.5 | C36: 10.8 | D36: 12.375 | F36: 4.5 | G36: 5.5 | H36: 7.75
A37: 31448 | B37: 18.63 | C37: 10.8 | D37: 12.375 | F37: 4.5 | G37: 5.5 | H37: 7.75
A38: 31449 | B38: 18.5 | C38: 11.47 | D38: 12.375 | F38: 4.5 | G38: 5.5 | H38: 7.75
A39: 31450 | B39: 18.63 | C39: 11.47 | D39: 12.375 | F39: 4.5 | G39: 5.5 | H39: 7.75
A40: 31451 | F40: 4.5 | G40: 5.5 | H40: 7.75
...

Sheet tbills
A1: Financial market statistics | B1: Canada3MTBill
A2: 31413 | B2: .. | P2: Canada 3mtbill | Q2: Bank of Canada, money market and other interest rates
A3: 31414 | B3: 9.39
A4: 31415 | B4: 9.68
A5: 31416 | B5: ..
A6: 31417 | B6: ..
A7: 31418 | B7: 9.82
A8: 31419 | B8: 9.72
A9: 31420 | B9: 9.91
A10: 31421 | B10: 9.96
A11: 31422 | B11: 9.89
A12: 31423 | B12: ..
A13: 31424 | B13: ..
A14: 31425 | B14: 10
A15: 31426 | B15: 10.09
A16: 31427 | B16: 10.13
A17: 31428 | B17: 10.12
A18: 31429 | B18: 10.09
A19: 31430 | B19: ..
A20: 31431 | B20: ..
A21: 31432 | B21: 10.1
A22: 31433 | B22: 10.22
A23: 31434 | B23: 10.07
A24: 31435 | B24: 10.09
A25: 31436 | B25: 10.28
A26: 31437 | B26: ..
A27: 31438 | B27: ..
A28: 31439 | B28: 10.43
A29: 31440 | B29: 10.5
A30: 31441 | B30: 10.45
A31: 31442 | B31: 10.7
A32: 31443 | B32: 10.59
A33: 31444 | B33: ..
A34: 31445 | B34: ..
A35: 31446 | B35: 10.74
A36: 31447 | B36: 10.78
A37: 31448 | B37: 11.08
A38: 31449 | B38: 11.23
A39: 31450 | B39: 11.33
A40: 31451 | B40: ..
...

Sheet Tracking
A1: Countries | B1: Returns | C1: Policy_interest rates | D1: Short-term interest rates
A2: USA | B2: SP500 | C2: yes | D2: 3M-Tbill
A3: Canada | B3: TSX Composite | C3: yes | D3: Canada 3m tbill
A4: Australia | B4: AUORD | C4: yes | D4: 3-month bank accepted bill
A5: United_Kingdom | B5: FTSE | C5: yes | D5: 3-month bond yield
A6: Hong_Kong | C6: No | D6: Not available
A7: Japan | B7: Nikkei225 | C7: Yes | D7: Official Discount Rates
A8: Netherlands | B8: ^AEX
